2024-08-08 11:26:37 [   DEBUG] [faker.factory] Looking for locale `en_US` in provider `faker.providers.address`. (factory.py:76)
2024-08-08 11:26:37 [   DEBUG] [faker.factory] Provider `faker.providers.address` has been localized to `en_US`. (factory.py:95)
2024-08-08 11:26:37 [   DEBUG] [faker.factory] Looking for locale `en_US` in provider `faker.providers.automotive`. (factory.py:76)
2024-08-08 11:26:37 [   DEBUG] [faker.factory] Provider `faker.providers.automotive` has been localized to `en_US`. (factory.py:95)
2024-08-08 11:26:37 [   DEBUG] [faker.factory] Looking for locale `en_US` in provider `faker.providers.bank`. (factory.py:76)
2024-08-08 11:26:37 [   DEBUG] [faker.factory] Specified locale `en_US` is not available for provider `faker.providers.bank`. Locale reset to `en_GB` for this provider. (factory.py:86)
2024-08-08 11:26:37 [   DEBUG] [faker.factory] Looking for locale `en_US` in provider `faker.providers.barcode`. (factory.py:76)
2024-08-08 11:26:37 [   DEBUG] [faker.factory] Provider `faker.providers.barcode` has been localized to `en_US`. (factory.py:95)
2024-08-08 11:26:37 [   DEBUG] [faker.factory] Looking for locale `en_US` in provider `faker.providers.color`. (factory.py:76)
2024-08-08 11:26:37 [   DEBUG] [faker.factory] Provider `faker.providers.color` has been localized to `en_US`. (factory.py:95)
2024-08-08 11:26:37 [   DEBUG] [faker.factory] Looking for locale `en_US` in provider `faker.providers.company`. (factory.py:76)
2024-08-08 11:26:37 [   DEBUG] [faker.factory] Provider `faker.providers.company` has been localized to `en_US`. (factory.py:95)
2024-08-08 11:26:37 [   DEBUG] [faker.factory] Looking for locale `en_US` in provider `faker.providers.credit_card`. (factory.py:76)
2024-08-08 11:26:37 [   DEBUG] [faker.factory] Provider `faker.providers.credit_card` has been localized to `en_US`. (factory.py:95)
2024-08-08 11:26:37 [   DEBUG] [faker.factory] Looking for locale `en_US` in provider `faker.providers.currency`. (factory.py:76)
2024-08-08 11:26:37 [   DEBUG] [faker.factory] Provider `faker.providers.currency` has been localized to `en_US`. (factory.py:95)
2024-08-08 11:26:37 [   DEBUG] [faker.factory] Looking for locale `en_US` in provider `faker.providers.date_time`. (factory.py:76)
2024-08-08 11:26:37 [   DEBUG] [faker.factory] Provider `faker.providers.date_time` has been localized to `en_US`. (factory.py:95)
2024-08-08 11:26:37 [   DEBUG] [faker.factory] Provider `faker.providers.emoji` does not feature localization. Specified locale `en_US` is not utilized for this provider. (factory.py:106)
2024-08-08 11:26:37 [   DEBUG] [faker.factory] Provider `faker.providers.file` does not feature localization. Specified locale `en_US` is not utilized for this provider. (factory.py:106)
2024-08-08 11:26:37 [   DEBUG] [faker.factory] Looking for locale `en_US` in provider `faker.providers.geo`. (factory.py:76)
2024-08-08 11:26:37 [   DEBUG] [faker.factory] Provider `faker.providers.geo` has been localized to `en_US`. (factory.py:95)
2024-08-08 11:26:37 [   DEBUG] [faker.factory] Looking for locale `en_US` in provider `faker.providers.internet`. (factory.py:76)
2024-08-08 11:26:37 [   DEBUG] [faker.factory] Provider `faker.providers.internet` has been localized to `en_US`. (factory.py:95)
2024-08-08 11:26:37 [   DEBUG] [faker.factory] Provider `faker.providers.isbn` does not feature localization. Specified locale `en_US` is not utilized for this provider. (factory.py:106)
2024-08-08 11:26:37 [   DEBUG] [faker.factory] Looking for locale `en_US` in provider `faker.providers.job`. (factory.py:76)
2024-08-08 11:26:37 [   DEBUG] [faker.factory] Provider `faker.providers.job` has been localized to `en_US`. (factory.py:95)
2024-08-08 11:26:37 [   DEBUG] [faker.factory] Looking for locale `en_US` in provider `faker.providers.lorem`. (factory.py:76)
2024-08-08 11:26:38 [   DEBUG] [faker.factory] Provider `faker.providers.lorem` has been localized to `en_US`. (factory.py:95)
2024-08-08 11:26:38 [   DEBUG] [faker.factory] Looking for locale `en_US` in provider `faker.providers.misc`. (factory.py:76)
2024-08-08 11:26:38 [   DEBUG] [faker.factory] Provider `faker.providers.misc` has been localized to `en_US`. (factory.py:95)
2024-08-08 11:26:38 [   DEBUG] [faker.factory] Looking for locale `en_US` in provider `faker.providers.passport`. (factory.py:76)
2024-08-08 11:26:38 [   DEBUG] [faker.factory] Provider `faker.providers.passport` has been localized to `en_US`. (factory.py:95)
2024-08-08 11:26:38 [   DEBUG] [faker.factory] Looking for locale `en_US` in provider `faker.providers.person`. (factory.py:76)
2024-08-08 11:26:38 [   DEBUG] [faker.factory] Provider `faker.providers.person` has been localized to `en_US`. (factory.py:95)
2024-08-08 11:26:38 [   DEBUG] [faker.factory] Looking for locale `en_US` in provider `faker.providers.phone_number`. (factory.py:76)
2024-08-08 11:26:38 [   DEBUG] [faker.factory] Provider `faker.providers.phone_number` has been localized to `en_US`. (factory.py:95)
2024-08-08 11:26:38 [   DEBUG] [faker.factory] Provider `faker.providers.profile` does not feature localization. Specified locale `en_US` is not utilized for this provider. (factory.py:106)
2024-08-08 11:26:38 [   DEBUG] [faker.factory] Provider `faker.providers.python` does not feature localization. Specified locale `en_US` is not utilized for this provider. (factory.py:106)
2024-08-08 11:26:38 [   DEBUG] [faker.factory] Provider `faker.providers.sbn` does not feature localization. Specified locale `en_US` is not utilized for this provider. (factory.py:106)
2024-08-08 11:26:38 [   DEBUG] [faker.factory] Looking for locale `en_US` in provider `faker.providers.ssn`. (factory.py:76)
2024-08-08 11:26:38 [   DEBUG] [faker.factory] Provider `faker.providers.ssn` has been localized to `en_US`. (factory.py:95)
2024-08-08 11:26:38 [   DEBUG] [faker.factory] Provider `faker.providers.user_agent` does not feature localization. Specified locale `en_US` is not utilized for this provider. (factory.py:106)
2024-08-08 11:26:38 [   ERROR] [django.request] Internal Server Error: / (log.py:241)
Traceback (most recent call last):
  File "C:\Users\mrcra\Desktop\PyTest\PyTest-Django-Full-Stack\venv\Lib\site-packages\django\core\handlers\exception.py", line 55, in inner
    response = get_response(request)
               ^^^^^^^^^^^^^^^^^^^^^
  File "C:\Users\mrcra\Desktop\PyTest\PyTest-Django-Full-Stack\venv\Lib\site-packages\django\core\handlers\base.py", line 197, in _get_response
    response = wrapped_callback(request, *callback_args, **callback_kwargs)
               ^^^^^^^^^^^^^^^^^^^^^^^^^^^^^^^^^^^^^^^^^^^^^^^^^^^^^^^^^^^^
  File "C:\Users\mrcra\Desktop\PyTest\PyTest-Django-Full-Stack\base\views.py", line 77, in home
    room_count = rooms.count()
                 ^^^^^^^^^^^^^
  File "C:\Users\mrcra\Desktop\PyTest\PyTest-Django-Full-Stack\venv\Lib\site-packages\django\db\models\query.py", line 620, in count
    return self.query.get_count(using=self.db)
           ^^^^^^^^^^^^^^^^^^^^^^^^^^^^^^^^^^^
  File "C:\Users\mrcra\Desktop\PyTest\PyTest-Django-Full-Stack\venv\Lib\site-packages\django\db\models\sql\query.py", line 629, in get_count
    return obj.get_aggregation(using, {"__count": Count("*")})["__count"]
           ^^^^^^^^^^^^^^^^^^^^^^^^^^^^^^^^^^^^^^^^^^^^^^^^^^^
  File "C:\Users\mrcra\Desktop\PyTest\PyTest-Django-Full-Stack\venv\Lib\site-packages\django\db\models\sql\query.py", line 615, in get_aggregation
    result = compiler.execute_sql(SINGLE)
             ^^^^^^^^^^^^^^^^^^^^^^^^^^^^
  File "C:\Users\mrcra\Desktop\PyTest\PyTest-Django-Full-Stack\venv\Lib\site-packages\django\db\models\sql\compiler.py", line 1560, in execute_sql
    cursor = self.connection.cursor()
             ^^^^^^^^^^^^^^^^^^^^^^^^
  File "C:\Users\mrcra\Desktop\PyTest\PyTest-Django-Full-Stack\venv\Lib\site-packages\django\utils\asyncio.py", line 26, in inner
    return func(*args, **kwargs)
           ^^^^^^^^^^^^^^^^^^^^^
  File "C:\Users\mrcra\Desktop\PyTest\PyTest-Django-Full-Stack\venv\Lib\site-packages\django\db\backends\base\base.py", line 316, in cursor
    return self._cursor()
           ^^^^^^^^^^^^^^
  File "C:\Users\mrcra\Desktop\PyTest\PyTest-Django-Full-Stack\venv\Lib\site-packages\django\db\backends\base\base.py", line 292, in _cursor
    self.ensure_connection()
  File "C:\Users\mrcra\Desktop\PyTest\PyTest-Django-Full-Stack\venv\Lib\site-packages\pytest_django\plugin.py", line 803, in _blocking_wrapper
    raise RuntimeError(
RuntimeError: Database access not allowed, use the "django_db" mark, or the "db" or "transactional_db" fixtures to enable it.
